Workbook

Sheet 1 Feb'26
A5: Operation Date | D5: 01 Feb' 2026
A7: I. Production
A8: Sect. | C8: Description | F8: Capacity | G8: Shift I | I8: Storage | J8: Shift II | L8: Storage | M8: Shift III | O8: Storage | P8: To Day | Q8: MTD | R8: D. Time
F9: MT/Day | G9: Product | H9: D.Time | I9: 122T... | J9: Product | K9: D.Time | L9: 122T... | M9: Product | N9: D.Time | O9: 122T... | R9: MTD
A10: 101 | C10: Feed ( CPKO / RBDPS ) | F10: 300 | G10: 8.634 | H10: 6 | I10: T-01 | J10: 40.947 | K10: 0 | L10: T-01 | M10: 24.377 | N10: 0 | O10: T-01 | P10: =G10+J10+M10 -> 73.958 | Q10: =P10 -> 73.958 | R10: =H10+K10+N10 -> 6
C11: Crude Fatty Acid | F11: 283 | G11: 0 | I11: T- | J11: 1.673 | L11: T-21 | M11: 25.379 | O11: T-21 | P11: =G11+J11+M11 -> 27.052 | Q11: =P11 -> 27.052
C12: Glycerine Water | F12: 231 | G12: 14.18 | I12: T-10 | J12: 27.672 | L12: T-10 | M12: 8.11 | O12: T-10 | P12: =G12+J12+M12 -> 49.962 | Q12: =P12 -> 49.962
A13: 102 | C13: Glycerine Water Feed | F13: 120 | G13: 0 | H13: 8 | I13: T-10 | J13: 0 | K13: 8 | L13: T- | M13: 0 | N13: 8 | O13: T- | P13: =G13+J13+M13 -> 0 | Q13: =P13 -> 0 | R13: =H13+K13+N13 -> 24
C14: Treated Glycerine Water | F14: 120 | G14: 0 | I14: T-13 | J14: 0 | L14: T- | M14: 0 | O14: T- | P14: =G14+J14+M14 -> 0 | Q14: =P14 -> 0
A15: 103 | C15: Treated Gly Water Feed | F15: 120 | G15: 37.681 | H15: 0 | I15: T-13 | J15: 36.068 | K15: 0 | L15: T-13 | M15: 24.664 | N15: 0 | O15: T-13 | P15: =G15+J15+M15 -> 98.413 | Q15: =P15 -> 98.413 | R15: =H15+K15+N15 -> 0
C16: Crude Glycerine | F16: 41 | G16: 12.714 | I16: T-14 | J16: 12.819 | L16: T-14 | M16: 12.338 | O16: T-14 | P16: =G16+J16+M16 -> 37.871 | Q16: =P16 -> 37.871
A17: 104 | C17: Crude Glycerine Feed | F17: 49 | G17: 11.829 | H17: 0 | I17: T-14 | J17: 12.011 | K17: 0 | L17: T-14 | M17: 11.748 | N17: 0 | O17: T-14 | P17: =G17+J17+M17 -> 35.588 | Q17: =P17 -> 35.588 | R17: =H17+K17+N17 -> 0
C18: Refined Glycerine | F18: 40 | G18: 11.428 | I18: T-23 | J18: 13.524 | L18: T-23 | M18: 12.701 | O18: T-23 | P18: =G18+J18+M18 -> 37.653 | Q18: =P18 -> 37.653
C19: Glycerine Dist. II | F19: 2.21 | G19: 1.022 | I19: T-10 | J19: 0.8 | L19: T-10 | M19: 0.87 | O19: T-10 | P19: =G19+J19+M19 -> 2.692 | Q19: =P19 -> 2.692
C20: Pitch Glycerine | F20: 1.2 | G20: 0.375 | I20: Drum | J20: 0 | L20: Drum | M20: 0 | O20: Drum | P20: =G20+J20+M20 -> 0.375 | Q20: =P20 -> 0.375
A21: 105 | C21: Crude F.Acid / Feed I | F21: 300 | G21: 23.108 | H21: 5.5 | I21: T-20 | J21: 0 | K21: 8 | L21: T- | M21: 0 | N21: 8 | O21: T- | P21: =G21+J21+M21 -> 23.108 | Q21: =P21 -> 23.108 | R21: =H21+K21+N21 -> 21.5
C22: Hydro F.Acid / Feed II | F22: 170 | G22: 0 | I22: - | J22: 0 | L22: - | M22: 0 | O22: - | P22: =G22+J22+M22 -> 0 | Q22: =P22 -> 0
C23: Light End | F23: 1.80 | G23: 0 | I23: - | J23: 0 | L23: - | M23: 0 | O23: - | P23: =G23+J23+M23 -> 0 | Q23: =P23 -> 0
C24: Top Fraction / C6-8 | F24: 1.56 | G24: 0.073 | I24: T-90 | J24: 0 | L24: T- | M24: 0 | O24: T- | P24: =G24+J24+M24 -> 0.073 | Q24: =P24 -> 0.073
C25: Side Fraction I / C8-10 | F25: 23.06 | G25: 1.731 | I25: F-06 | J25: 0 | L25: F- | M25: 0 | O25: F- | P25: =G25+J25+M25 -> 1.731 | Q25: =P25 -> 1.731
C26: Side Fr action II / C12-70 | F26: 188.33 | G26: 13.389 | I26: T-31 | J26: 0 | L26: T- | M26: 0 | O26: T- | P26: =G26+J26+M26 -> 13.389 | Q26: =P26 -> 13.389
C27: Side Fraction C16-98 | F27: 141.23 | G27: 0 | I27: - | J27: 0 | L27: - | M27: 0 | O27: - | P27: =G27+J27+M27 -> 0 | Q27: =P27 -> 0
C28: Distillate / C16-18 (PK) | F28: 75.55 | G28: 5.778 | I28: T-34 | J28: 0 | L28: T- | M28: 0 | O28: T- | P28: =G28+J28+M28 -> 5.778 | Q28: =P28 -> 5.778
C29: Distillate / C16-18 (PS) | F29: 146.71 | G29: 0 | I29: - | J29: 0 | L29: - | M29: 0 | O29: - | P29: =G29+J29+M29 -> 0 | Q29: =P29 -> 0
C30: Heavy End | F30: N/A | G30: 0.753 | I30: T-26 | J30: 0 | L30: T- | M30: 0 | O30: T- | P30: =G30+J30+M30 -> 0.753 | Q30: =P30 -> 0.753
C31: Fatty Acid Residue | F31: 9.7 | G31: 0 | I31: T-35 | J31: 0 | L31: T- | M31: 0 | O31: T- | P31: =G31+J31+M31 -> 0 | Q31: =P31 -> 0
A32: 107 | C32: C16-18 UH Feed | F32: 201 | G32: 0 | H32: 8 | I32: T- | J32: 0 | K32: 8 | L32: T- | M32: 0 | N32: 8 | O32: T- | P32: =G32+J32+M32 -> 0 | Q32: =P32 -> 0 | R32: =H32+K32+N32 -> 24
C33: C16-18 Hydro Product | F33: 200 | G33: 0 | I33: T- | J33: 0 | L33: T- | M33: 0 | O33: T- | P33: =G33+J33+M33 -> 0 | Q33: =P33 -> 0

Sheet 2 Feb'26 
A5: Operation Date | D5: 02 Feb' 2026
A7: I. Production
A8: Sect. | C8: Description | F8: Capacity | G8: Shift I | I8: Storage | J8: Shift II | L8: Storage | M8: Shift III | O8: Storage | P8: To Day | Q8: MTD | R8: D. Time
F9: MT/Day | G9: Product | H9: D.Time | I9: 122T... | J9: Product | K9: D.Time | L9: 122T... | M9: Product | N9: D.Time | O9: 122T... | R9: MTD
A10: 101 | C10: Feed ( CPKO / RBDPS ) | F10: 300 | G10: 0 | H10: 8 | I10: T-02 | J10: 0 | K10: 8 | L10: T-02 | M10: 23.9 | N10: 4 | O10: T-02 | P10: =G10+J10+M10 -> 23.9 | Q10: =P10+'1 Feb''26'!Q10 -> 97.858 | R10: =H10+K10+N10+'1 Feb''26'!R10 -> 26
C11: Crude Fatty Acid | F11: 283 | G11: 0 | I11: T-20 | J11: 0 | L11: T-20 | M11: 23.24 | O11: T-21 | P11: =G11+J11+M11 -> 23.24 | Q11: =P11+'1 Feb''26'!Q11 -> 50.292
C12: Glycerine Water | F12: 231 | G12: 0 | I12: T-10 | J12: 0 | L12: T-10 | M12: 2.202 | O12: T-10 | P12: =G12+J12+M12 -> 2.202 | Q12: =P12+'1 Feb''26'!Q12 -> 52.164
A13: 102 | C13: Glycerine Water Feed | F13: 120 | G13: 0 | H13: 8 | I13: T-10 | J13: 0 | K13: 8 | L13: T-10 | M13: 14.561 | N13: 8 | O13: T-10 | P13: =G13+J13+M13 -> 14.561 | Q13: =P13+'1 Feb''26'!Q13 -> 14.561 | R13: =H13+K13+N13+'1 Feb''26'!R13 -> 48
C14: Treated Glycerine Water | F14: 120 | G14: 0 | I14: T-13 | J14: 0 | L14: T-13 | M14: 0 | O14: T- | P14: =G14+J14+M14 -> 0 | Q14: =P14+'1 Feb''26'!Q14 -> 0
A15: 103 | C15: Treated Gly Water Feed | F15: 120 | G15: 0 | H15: 8 | I15: T-13 | J15: 0 | K15: 8 | L15: T-13 | M15: 0 | N15: 8 | O15: T- | P15: =G15+J15+M15 -> 0 | Q15: =P15+'1 Feb''26'!Q15 -> 98.413 | R15: =H15+K15+N15+'1 Feb''26'!R15 -> 24
C16: Crude Glycerine | F16: 41 | G16: 0 | I16: T-15 | J16: 0 | L16: T-15 | M16: 0 | O16: T- | P16: =G16+J16+M16 -> 0 | Q16: =P16+'1 Feb''26'!Q16 -> 37.871
A17: 104 | C17: Crude Glycerine Feed | F17: 49 | G17: 0 | H17: 4 | I17: T-15 | J17: 0 | K17: 8 | L17: T-15 | M17: 0 | N17: 8 | O17: T- | P17: =G17+J17+M17 -> 0 | Q17: =P17+'1 Feb''26'!Q17 -> 35.588 | R17: =H17+K17+N17+'1 Feb''26'!R17 -> 20
C18: Refined Glycerine | F18: 40 | G18: 0 | I18: T-23 | J18: 0 | L18: T-23 | M18: 0 | O18: T- | P18: =G18+J18+M18 -> 0 | Q18: =P18+'1 Feb''26'!Q18 -> 37.653
C19: Glycerine Dist. II | F19: 2.21 | G19: 0 | I19: T-10 | J19: 0 | L19: T-10 | M19: 0 | O19: T- | P19: =G19+J19+M19 -> 0 | Q19: =P19+'1 Feb''26'!Q19 -> 2.692
C20: Pitch Glycerine | F20: 1.2 | G20: 0 | I20: Drum | J20: 0 | L20: Drum | M20: 0 | O20: Drum | P20: =G20+J20+M20 -> 0 | Q20: =P20+'1 Feb''26'!Q20 -> 0.375
A21: 105 | C21: Crude F.Acid / Feed I | F21: 300 | G21: 0 | H21: 8 | I21: T-20 | J21: 0 | K21: 8 | L21: T-20 | M21: 0 | N21: 8 | O21: T- | P21: =G21+J21+M21 -> 0 | Q21: =P21+'1 Feb''26'!Q21 -> 23.108 | R21: =H21+K21+N21+'1 Feb''26'!R21 -> 45.5
C22: Hydro F.Acid / Feed II | F22: 170 | G22: 0 | I22: - | J22: 0 | L22: - | M22: 0 | O22: - | P22: =G22+J22+M22 -> 0 | Q22: =P22+'1 Feb''26'!Q22 -> 0
C23: Light End | F23: 1.80 | G23: 0 | I23: T-37 | J23: 0 | L23: T-37 | M23: 0 | O23: T- | P23: =G23+J23+M23 -> 0 | Q23: =P23+'1 Feb''26'!Q23 -> 0
C24: Top Fraction / C6-8 | F24: 1.56 | G24: 0 | I24: - | J24: 0 | L24: - | M24: 0 | O24: - | P24: =G24+J24+M24 -> 0 | Q24: =P24+'1 Feb''26'!Q24 -> 0.073
C25: Side Fraction I / C8-10 | F25: 23.06 | G25: 0 | I25: - | J25: 0 | L25: - | M25: 0 | O25: - | P25: =G25+J25+M25 -> 0 | Q25: =P25+'1 Feb''26'!Q25 -> 1.731
C26: Side Fr action II / C12-70 | F26: 188.33 | G26: 0 | I26: - | J26: 0 | L26: - | M26: 0 | O26: - | P26: =G26+J26+M26 -> 0 | Q26: =P26+'1 Feb''26'!Q26 -> 13.389
C27: Side Fraction C16-95 | F27: 141.23 | G27: 0 | I27: T-32 | J27: 0 | L27: T-32 | M27: 0 | O27: T- | P27: =G27+J27+M27 -> 0 | Q27: =P27+'1 Feb''26'!Q27 -> 0
C28: Distillate / C16-18 (PK) | F28: 75.55 | G28: 0 | I28: - | J28: 0 | L28: - | M28: 0 | O28: - | P28: =G28+J28+M28 -> 0 | Q28: =P28+'1 Feb''26'!Q28 -> 5.778
C29: Distillate / C16-18 (PO) | F29: 146.71 | G29: 0 | I29: T-28 | J29: 0 | L29: T-28 | M29: 0 | O29: T- | P29: =G29+J29+M29 -> 0 | Q29: =P29+'1 Feb''26'!Q29 -> 0
C30: Heavy End | F30: N/A | G30: 0 | I30: - | J30: 0 | L30: - | M30: 0 | O30: - | P30: =G30+J30+M30 -> 0 | Q30: =P30+'1 Feb''26'!Q30 -> 0.753
C31: Fatty Acid Residue | F31: 9.7 | G31: 0 | I31: T-35 | J31: 0 | L31: T-35 | M31: 0 | O31: T- | P31: =G31+J31+M31 -> 0 | Q31: =P31+'1 Feb''26'!Q31 -> 0
A32: 107 | C32: C16-18 UH Feed | F32: 201 | G32: 0 | H32: 8 | I32: T- | J32: 0 | K32: 8 | L32: T- | M32: 0 | N32: 8 | O32: T- | P32: =G32+J32+M32 -> 0 | Q32: =P32+'1 Feb''26'!Q32 -> 0 | R32: =H32+K32+N32+'1 Feb''26'!R32 -> 48
C33: C16-18 Hydro Product | F33: 200 | G33: 0 | I33: T- | J33: 0 | L33: T- | M33: 0 | O33: T- | P33: =G33+J33+M33 -> 0 | Q33: =P33+'1 Feb''26'!Q33 -> 0

Sheet 3 Feb'26
A5: Operation Date | D5: 03 Feb' 2026
A7: I. Production
A8: Sect. | C8: Description | F8: Capacity | G8: Shift I | I8: Storage | J8: Shift II | L8: Storage | M8: Shift III | O8: Storage | P8: To Day | Q8: MTD | R8: D. Time
F9: MT/Day | G9: Product | H9: D.Time | I9: 122T... | J9: Product | K9: D.Time | L9: 122T... | M9: Product | N9: D.Time | O9: 122T... | R9: MTD
A10: 101 | C10: Feed ( CPKO / RBDPS ) | F10: 300 | G10: 42.632 | H10: 0 | I10: T-02 | J10: 21.881 | K10: 4 | L10: T-02 | M10: 0 | N10: 8 | O10: T-02 | P10: =G10+J10+M10 -> 64.513 | Q10: =P10+'2 Feb''26 '!Q10 -> 162.371 | R10: =H10+K10+N10+'2 Feb''26 '!R10 -> 38
C11: Crude Fatty Acid | F11: 283 | G11: 39.964 | I11: T-21 | J11: 38.622 | L11: T-21 | M11: 26.38 | O11: T-21 | P11: =G11+J11+M11 -> 104.966 | Q11: =P11+'2 Feb''26 '!Q11 -> 155.258
C12: Glycerine Water | F12: 231 | G12: 19.952 | I12: T-10 | J12: 9.981 | L12: T-10 | M12: 4.646 | O12: T-10 | P12: =G12+J12+M12 -> 34.579 | Q12: =P12+'2 Feb''26 '!Q12 -> 86.743
A13: 102 | C13: Glycerine Water Feed | F13: 120 | G13: 20.305 | H13: 7 | I13: T-10 | J13: 19.935 | K13: 0 | L13: T-10 | M13: 18.617 | N13: 0 | O13: T-10 | P13: =G13+J13+M13 -> 58.857 | Q13: =P13+'2 Feb''26 '!Q13 -> 73.418 | R13: =H13+K13+N13+'2 Feb''26 '!R13 -> 55
C14: Treated Glycerine Water | F14: 120 | G14: 12.338 | H14: 0 | I14: T-13 | J14: 25.013 | L14: T-13 | M14: 6.113 | O14: T-13 | P14: =G14+J14+M14 -> 43.464 | Q14: =P14+'2 Feb''26 '!Q14 -> 43.464
A15: 103 | C15: Treated Gly Water Feed | F15: 120 | G15: 0 | H15: 8 | I15: T- | J15: 0 | K15: 8 | L15: T- | M15: 0 | N15: 8 | O15: T- | P15: =G15+J15+M15 -> 0 | Q15: =P15+'2 Feb''26 '!Q15 -> 98.413 | R15: =H15+K15+N15+'2 Feb''26 '!R15 -> 48
C16: Crude Glycerine | F16: 41 | G16: 0 | I16: T- | J16: 0 | L16: T- | M16: 0 | O16: T- | P16: =G16+J16+M16 -> 0 | Q16: =P16+'2 Feb''26 '!Q16 -> 37.871
A17: 104 | C17: Crude Glycerine Feed | F17: 49 | G17: 0 | H17: 8 | I17: T- | J17: 0 | K17: 8 | L17: T- | M17: 0 | N17: 8 | O17: T- | P17: =G17+J17+M17 -> 0 | Q17: =P17+'2 Feb''26 '!Q17 -> 35.588 | R17: =H17+K17+N17+'2 Feb''26 '!R17 -> 44
C18: Refined Glycerine | F18: 40 | G18: 0 | I18: T- | J18: 0 | L18: T- | M18: 0 | O18: T- | P18: =G18+J18+M18 -> 0 | Q18: =P18+'2 Feb''26 '!Q18 -> 37.653
C19: Glycerine Dist. II | F19: 2.21 | G19: 0 | I19: T- | J19: 0 | L19: T- | M19: 0 | O19: T- | P19: =G19+J19+M19 -> 0 | Q19: =P19+'2 Feb''26 '!Q19 -> 2.692
C20: Pitch Glycerine | F20: 1.2 | G20: 0 | I20: Drum | J20: 0.5 | L20: Drum | M20: 0 | O20: Drum | P20: =G20+J20+M20 -> 0.5 | Q20: =P20+'2 Feb''26 '!Q20 -> 0.875
A21: 105 | C21: Crude F.Acid / Feed I | F21: 300 | G21: 0 | H21: 8 | I21: T- | J21: 0 | K21: 8 | L21: T- | M21: 0 | N21: 8 | O21: T- | P21: =G21+J21+M21 -> 0 | Q21: =P21+'2 Feb''26 '!Q21 -> 23.108 | R21: =H21+K21+N21+'2 Feb''26 '!R21 -> 69.5
C22: Hydro F.Acid / Feed II | F22: 170 | G22: 0 | I22: - | J22: 0 | L22: - | M22: 0 | O22: - | P22: =G22+J22+M22 -> 0 | Q22: =P22+'2 Feb''26 '!Q22 -> 0
C23: Light End | F23: 1.80 | G23: 0 | I23: T- | J23: 0 | L23: T- | M23: 0 | O23: T- | P23: =G23+J23+M23 -> 0 | Q23: =P23+'2 Feb''26 '!Q23 -> 0
C24: Top Fraction / C6-8 | F24: 1.56 | G24: 0 | I24: - | J24: 0 | L24: - | M24: 0 | O24: - | P24: =G24+J24+M24 -> 0 | Q24: =P24+'2 Feb''26 '!Q24 -> 0.073
C25: Side Fraction I / C8-10 | F25: 23.06 | G25: 0 | I25: - | J25: 0 | L25: - | M25: 0 | O25: - | P25: =G25+J25+M25 -> 0 | Q25: =P25+'2 Feb''26 '!Q25 -> 1.731
C26: Side Fr action II / C12-70 | F26: 188.33 | G26: 0 | I26: - | J26: 0 | L26: - | M26: 0 | O26: - | P26: =G26+J26+M26 -> 0 | Q26: =P26+'2 Feb''26 '!Q26 -> 13.389
C27: Side Fraction C16-95 | F27: 141.23 | G27: 0 | I27: T- | J27: 0 | L27: T- | M27: 0 | O27: T- | P27: =G27+J27+M27 -> 0 | Q27: =P27+'2 Feb''26 '!Q27 -> 0
C28: Distillate / C16-18 (PK) | F28: 75.55 | G28: 0 | I28: - | J28: 0 | L28: - | M28: 0 | O28: - | P28: =G28+J28+M28 -> 0 | Q28: =P28+'2 Feb''26 '!Q28 -> 5.778
C29: Distillate / C16-18 (PS) | F29: 146.71 | G29: 0 | I29: T- | J29: 0 | L29: T- | M29: 0 | O29: T- | P29: =G29+J29+M29 -> 0 | Q29: =P29+'2 Feb''26 '!Q29 -> 0
C30: Heavy End | F30: N/A | G30: 0 | I30: - | J30: 0 | L30: - | M30: 0 | O30: - | P30: =G30+J30+M30 -> 0 | Q30: =P30+'2 Feb''26 '!Q30 -> 0.753
C31: Fatty Acid Residue | F31: 9.7 | G31: 0 | I31: T- | J31: 0 | L31: T- | M31: 0 | O31: T- | P31: =G31+J31+M31 -> 0 | Q31: =P31+'2 Feb''26 '!Q31 -> 0
A32: 107 | C32: C16-18 UH Feed | F32: 201 | G32: 0 | H32: 8 | I32: T- | J32: 0 | K32: 8 | L32: T- | M32: 0 | N32: 8 | O32: T- | P32: =G32+J32+M32 -> 0 | Q32: =P32+'2 Feb''26 '!Q32 -> 0 | R32: =H32+K32+N32+'2 Feb''26 '!R32 -> 72
C33: C16-18 Hydro Product | F33: 200 | G33: 0 | I33: T- | J33: 0 | L33: T- | M33: 0 | O33: T- | P33: =G33+J33+M33 -> 0 | Q33: =P33+'2 Feb''26 '!Q33 -> 0

Sheet 4 Feb'26
A5: Operation Date | D5: 04 Feb' 2026
A7: I. Production
A8: Sect. | C8: Description | F8: Capacity | G8: Shift I | I8: Storage | J8: Shift II | L8: Storage | M8: Shift III | O8: Storage | P8: To Day | Q8: MTD | R8: D. Time
F9: MT/Day | G9: Product | H9: D.Time | I9: 122T... | J9: Product | K9: D.Time | L9: 122T... | M9: Product | N9: D.Time | O9: 122T... | R9: MTD
A10: 101 | C10: Feed ( CPKO / RBDPS ) | F10: 300 | G10: 14.831 | H10: 8 | I10: T-01 | J10: 43.526 | K10: 6.5 | L10: T-01 | M10: 54.365 | N10: 0 | O10: T-01 | P10: =G10+J10+M10 -> 112.722 | Q10: =P10+'3 Feb''26'!Q10 -> 275.093 | R10: =H10+K10+N10+'3 Feb''26'!R10 -> 52.5
C11: Crude Fatty Acid | F11: 283 | G11: 0 | I11: T- | J11: 10.717 | L11: NT/T-20 | M11: 55.411 | O11: T-20 | P11: =G11+J11+M11 -> 66.128 | Q11: =P11+'3 Feb''26'!Q11 -> 221.386
C12: Glycerine Water | F12: 231 | G12: 22.795 | I12: T-10 | J12: 45.725 | L12: T-10 | M12: 38.442 | O12: T-10 | P12: =G12+J12+M12 -> 106.962 | Q12: =P12+'3 Feb''26'!Q12 -> 193.705
A13: 102 | C13: Glycerine Water Feed | F13: 120 | G13: 20.378 | H13: 0 | I13: T-10 | J13: 21.973 | K13: 0 | L13: T-10 | M13: 21.998 | N13: 0 | O13: T-10 | P13: =G13+J13+M13 -> 64.349 | Q13: =P13+'3 Feb''26'!Q13 -> 137.767 | R13: =H13+K13+N13+'3 Feb''26'!R13 -> 55
C14: Treated Glycerine Water | F14: 120 | G14: 22.808 | I14: T-13 | J14: 19.312 | L14: T-13 | M14: 0 | O14: T-13 | P14: =G14+J14+M14 -> 42.12 | Q14: =P14+'3 Feb''26'!Q14 -> 85.584
A15: 103 | C15: Treated Gly Water Feed | F15: 120 | G15: 16.042 | H15: 4.5 | I15: T-13 | J15: 23.631 | K15: 0 | L15: T-13 | M15: 23.466 | N15: 0 | O15: T-13 | P15: =G15+J15+M15 -> 63.139 | Q15: =P15+'3 Feb''26'!Q15 -> 161.552 | R15: =H15+K15+N15+'3 Feb''26'!R15 -> 52.5
C16: Crude Glycerine | F16: 41 | G16: 4.812 | I16: T-13/14 | J16: 12.409 | L16: T-14 | M16: 9.801 | O16: T-14 | P16: =G16+J16+M16 -> 27.022 | Q16: =P16+'3 Feb''26'!Q16 -> 64.893
A17: 104 | C17: Crude Glycerine Feed | F17: 49 | G17: 0 | H17: 8 | I17: T- | J17: 0 | K17: 8 | L17: T- | M17: 0 | N17: 8 | O17: T- | P17: =G17+J17+M17 -> 0 | Q17: =P17+'3 Feb''26'!Q17 -> 35.588 | R17: =H17+K17+N17+'3 Feb''26'!R17 -> 68
C18: Refined Glycerine | F18: 40 | G18: 0 | I18: T- | J18: 0 | L18: T- | M18: 0 | O18: T- | P18: =G18+J18+M18 -> 0 | Q18: =P18+'3 Feb''26'!Q18 -> 37.653
C19: Glycerine Dist. II | F19: 2.21 | G19: 0 | I19: T- | J19: 0 | L19: T- | M19: 0 | O19: T- | P19: =G19+J19+M19 -> 0 | Q19: =P19+'3 Feb''26'!Q19 -> 2.692
C20: Pitch Glycerine | F20: 1.2 | G20: 0 | I20: Drum | J20: 0 | L20: Drum | M20: 0 | O20: Drum | P20: =G20+J20+M20 -> 0 | Q20: =P20+'3 Feb''26'!Q20 -> 0.875
A21: 105 | C21: Crude F.Acid / Feed I | F21: 300 | G21: 0 | H21: 8 | I21: T- | J21: 0 | K21: 8 | L21: T- | M21: 0 | N21: 8 | O21: T- | P21: =G21+J21+M21 -> 0 | Q21: =P21+'3 Feb''26'!Q21 -> 23.108 | R21: =H21+K21+N21+'3 Feb''26'!R21 -> 93.5
C22: Hydro F.Acid / Feed II | F22: 170 | G22: 0 | I22: - | J22: 0 | L22: - | M22: 0 | O22: - | P22: =G22+J22+M22 -> 0 | Q22: =P22+'3 Feb''26'!Q22 -> 0
C23: Light End | F23: 1.80 | G23: 0 | I23: T- | J23: 0 | L23: T- | M23: 0 | O23: T- | P23: =G23+J23+M23 -> 0 | Q23: =P23+'3 Feb''26'!Q23 -> 0
C24: Top Fraction / C6-8 | F24: 1.56 | G24: 0 | I24: - | J24: 0 | L24: - | M24: 0 | O24: - | P24: =G24+J24+M24 -> 0 | Q24: =P24+'3 Feb''26'!Q24 -> 0.073
C25: Side Fraction I / C8-10 | F25: 23.06 | G25: 0 | I25: - | J25: 0 | L25: - | M25: 0 | O25: - | P25: =G25+J25+M25 -> 0 | Q25: =P25+'3 Feb''26'!Q25 -> 1.731
C26: Side Fr action II / C12-70 | F26: 188.33 | G26: 0 | I26: - | J26: 0 | L26: - | M26: 0 | O26: - | P26: =G26+J26+M26 -> 0 | Q26: =P26+'3 Feb''26'!Q26 -> 13.389
C27: Side Fraction C16-95 | F27: 141.23 | G27: 0 | I27: T- | J27: 0 | L27: T- | M27: 0 | O27: T- | P27: =G27+J27+M27 -> 0 | Q27: =P27+'3 Feb''26'!Q27 -> 0
C28: Distillate / C16-18 (PK) | F28: 75.55 | G28: 0 | I28: - | J28: 0 | L28: - | M28: 0 | O28: - | P28: =G28+J28+M28 -> 0 | Q28: =P28+'3 Feb''26'!Q28 -> 5.778
C29: Distillate / C16-18 (PO) | F29: 146.71 | G29: 0 | I29: T- | J29: 0 | L29: T- | M29: 0 | O29: T- | P29: =G29+J29+M29 -> 0 | Q29: =P29+'3 Feb''26'!Q29 -> 0
C30: Heavy End | F30: N/A | G30: 0 | I30: - | J30: 0 | L30: - | M30: 0 | O30: - | P30: =G30+J30+M30 -> 0 | Q30: =P30+'3 Feb''26'!Q30 -> 0.753
C31: Fatty Acid Residue | F31: 9.7 | G31: 0 | I31: T- | J31: 0 | L31: T- | M31: 0 | O31: T- | P31: =G31+J31+M31 -> 0 | Q31: =P31+'3 Feb''26'!Q31 -> 0
A32: 107 | C32: C16-18 UH Feed | F32: 201 | G32: 0 | H32: 8 | I32: T- | J32: 0 | K32: 8 | L32: T- | M32: 0 | N32: 8 | O32: T- | P32: =G32+J32+M32 -> 0 | Q32: =P32+'3 Feb''26'!Q32 -> 0 | R32: =H32+K32+N32+'3 Feb''26'!R32 -> 96
C33: C16-18 Hydro Product | F33: 200 | G33: 0 | I33: T- | J33: 0 | L33: T- | M33: 0 | O33: T- | P33: =G33+J33+M33 -> 0 | Q33: =P33+'3 Feb''26'!Q33 -> 0

Sheet 5 Feb'26
A5: Operation Date | D5: 05 Feb' 2026
A7: I. Production
A8: Sect. | C8: Description | F8: Capacity | G8: Shift I | I8: Storage | J8: Shift II | L8: Storage | M8: Shift III | O8: Storage | P8: To Day | Q8: MTD | R8: D. Time
F9: MT/Day | G9: Product | H9: D.Time | I9: 122T... | J9: Product | K9: D.Time | L9: 122T... | M9: Product | N9: D.Time | O9: 122T... | R9: MTD
A10: 101 | C10: Feed ( CPKO / RBDPS ) | F10: 300 | G10: 80.488 | H10: 0 | I10: T-01 | J10: 84.906 | K10: 0 | L10: T-01 | M10: 98.214 | N10: 0 | O10: T-01 | P10: =G10+J10+M10 -> 263.608 | Q10: =P10+'4 Feb''26'!Q10 -> 538.701 | R10: =H10+K10+N10+'4 Feb''26'!R10 -> 52.5
C11: Crude Fatty Acid | F11: 283 | G11: 76.48 | I11: T-20 | J11: 81.611 | L11: T-20 | M11: 95.745 | O11: T-20 | P11: =G11+J11+M11 -> 253.836 | Q11: =P11+'4 Feb''26'!Q11 -> 475.222
C12: Glycerine Water | F12: 231 | G12: 54.758 | I12: T-10 | J12: 57.345 | L12: T-10 | M12: 64.708 | O12: T-10 | P12: =G12+J12+M12 -> 176.811 | Q12: =P12+'4 Feb''26'!Q12 -> 370.516
A13: 102 | C13: Glycerine Water Feed | F13: 120 | G13: 22.63 | H13: 0 | I13: T-10 | J13: 30.89 | K13: 0 | L13: T-10 | M13: 38.385 | N13: 0 | O13: T-10 | P13: =G13+J13+M13 -> 91.905 | Q13: =P13+'4 Feb''26'!Q13 -> 229.672 | R13: =H13+K13+N13+'4 Feb''26'!R13 -> 55
C14: Treated Glycerine Water | F14: 120 | G14: 22.764 | I14: T-13 | J14: 3.83 | L14: T-13 | M14: 31.019 | O14: T-13 | P14: =G14+J14+M14 -> 57.613 | Q14: =P14+'4 Feb''26'!Q14 -> 143.197
A15: 103 | C15: Treated Gly Water Feed | F15: 120 | G15: 24.086 | H15: 0 | I15: T-13 | J15: 24.09 | K15: 0 | L15: T-13 | M15: 21.122 | N15: 0 | O15: T-13 | P15: =G15+J15+M15 -> 69.298 | Q15: =P15+'4 Feb''26'!Q15 -> 230.85 | R15: =H15+K15+N15+'4 Feb''26'!R15 -> 52.5
C16: Crude Glycerine | F16: 41 | G16: 9.634 | I16: T-14 | J16: 9.641 | L16: T-14 | M16: 9.489 | O16: T-14 | P16: =G16+J16+M16 -> 28.764 | Q16: =P16+'4 Feb''26'!Q16 -> 93.657
A17: 104 | C17: Crude Glycerine Feed | F17: 49 | G17: 9.476 | H17: 8 | I17: T-14 | J17: 7.62 | K17: 0 | L17: T-14 | M17: 10.51 | N17: 0 | O17: T-14 | P17: =G17+J17+M17 -> 27.606 | Q17: =P17+'4 Feb''26'!Q17 -> 63.194 | R17: =H17+K17+N17+'4 Feb''26'!R17 -> 76
C18: Refined Glycerine | F18: 40 | G18: 0 | I18: T-14/16 | J18: 5.182 | L18: T-16 | M18: 9.954 | O18: T-16 | P18: =G18+J18+M18 -> 15.136 | Q18: =P18+'4 Feb''26'!Q18 -> 52.789
C19: Glycerine Dist. II | F19: 2.21 | G19: 0.15 | I19: T-10 | J19: 0.505 | L19: T-10 | M19: 0.506 | O19: T-10 | P19: =G19+J19+M19 -> 1.161 | Q19: =P19+'4 Feb''26'!Q19 -> 3.853
C20: Pitch Glycerine | F20: 0 | G20: 0 | I20: Drum | J20: 0 | L20: Drum | M20: 0.5 | O20: Drum | P20: =G20+J20+M20 -> 0.5 | Q20: =P20+'4 Feb''26'!Q20 -> 1.375
A21: 105 | C21: Crude F.Acid / Feed I | F21: 300 | G21: 42.797 | H21: 8 | I21: T- | J21: 16.991 | K21: 6 | L21: T-20 | M21: 83.54 | N21: 0 | O21: T-20 | P21: =G21+J21+M21 -> 143.328 | Q21: =P21+'4 Feb''26'!Q21 -> 166.436 | R21: =H21+K21+N21+'4 Feb''26'!R21 -> 107.5
C22: Hydro F.Acid / Feed II | F22: 170 | G22: 0 | I22: - | J22: 0 | L22: - | M22: 0 | O22: - | P22: =G22+J22+M22 -> 0 | Q22: =P22+'4 Feb''26'!Q22 -> 0
C23: Light End | F23: 1.80 | G23: 0 | I23: T- | J23: 0 | L23: - | M23: 0 | O23: - | P23: =G23+J23+M23 -> 0 | Q23: =P23+'4 Feb''26'!Q23 -> 0
C24: Top Fraction / C6-8 | F24: 1.56 | G24: 0 | I24: - | J24: 0.04 | L24: T-20/90 | M24: 0.186 | O24: T-90 | P24: =G24+J24+M24 -> 0.226 | Q24: =P24+'4 Feb''26'!Q24 -> 0.299
C25: Side Fraction I / C8-10 | F25: 23.06 | G25: 0 | I25: - | J25: 1.179 | L25: T-20/F-06 | M25: 6.128 | O25: F-06/07 | P25: =G25+J25+M25 -> 7.307 | Q25: =P25+'4 Feb''26'!Q25 -> 9.038
C26: Side Fr action II / C12-70 | F26: 188.33 | G26: 0 | I26: - | J26: 9.383 | L26: T-20/31 | M26: 47.223 | O26: T-31 | P26: =G26+J26+M26 -> 56.606 | Q26: =P26+'4 Feb''26'!Q26 -> 69.995
C27: Side Fraction C16-95 | F27: 141.23 | G27: 0 | I27: T- | J27: 0 | L27: - | M27: 0 | O27: - | P27: =G27+J27+M27 -> 0 | Q27: =P27+'4 Feb''26'!Q27 -> 0
C28: Distillate / C16-18 (PK) | F28: 75.55 | G28: 0 | I28: - | J28: 3.966 | L28: T-20/34 | M28: 21.496 | O28: T-34 | P28: =G28+J28+M28 -> 25.462 | Q28: =P28+'4 Feb''26'!Q28 -> 31.24
C29: Distillate / C16-18 (PS) | F29: 146.71 | G29: 0 | I29: T- | J29: 0 | L29: - | M29: 0 | O29: - | P29: =G29+J29+M29 -> 0 | Q29: =P29+'4 Feb''26'!Q29 -> 0
C30: Heavy End | F30: N/A | G30: 0 | I30: - | J30: 0.432 | L30: T-20/26 | M30: 1.724 | O30: T-26 | P30: =G30+J30+M30 -> 2.156 | Q30: =P30+'4 Feb''26'!Q30 -> 2.909
C31: Fatty Acid Residue | F31: 9.7 | G31: 0 | I31: T- | J31: 0.205 | L31: T-20/35 | M31: 0.605 | O31: T-35 | P31: =G31+J31+M31 -> 0.81 | Q31: =P31+'4 Feb''26'!Q31 -> 0.81
A32: 107 | C32: C16-18 UH Feed | F32: 201 | G32: 0 | H32: 8 | I32: T- | J32: 0 | K32: 8 | L32: T- | M32: 0 | N32: 8 | O32: T- | P32: =G32+J32+M32 -> 0 | Q32: =P32+'4 Feb''26'!Q32 -> 0 | R32: =H32+K32+N32+'4 Feb''26'!R32 -> 120
C33: C16-18 Hydro Product | F33: 200 | G33: 0 | I33: T- | J33: 0 | L33: T- | M33: 0 | O33: T- | P33: =G33+J33+M33 -> 0 | Q33: =P33+'4 Feb''26'!Q33 -> 0

Sheet 6 Feb'26
A5: Operation Date | D5: 06 Feb' 2026
A7: I. Production
A8: Sect. | C8: Description | F8: Capacity | G8: Shift I | I8: Storage | J8: Shift II | L8: Storage | M8: Shift III | O8: Storage | P8: To Day | Q8: MTD | R8: D. Time
F9: MT/Day | G9: Product | H9: D.Time | I9: 122T... | J9: Product | K9: D.Time | L9: 122T... | M9: Product | N9: D.Time | O9: 122T... | R9: MTD
A10: 101 | C10: Feed ( CPKO / RBDPS ) | F10: 300 | G10: 99.902 | H10: 0 | I10: T-01 | J10: 98.628 | K10: 0 | L10: T-01 | M10: 35.292 | N10: 3 | O10: T-01 | P10: =G10+J10+M10 -> 233.822 | Q10: =P10+'5 Feb''26'!Q10 -> 772.523 | R10: =H10+K10+N10+'5 Feb''26'!R10 -> 55.5
C11: Crude Fatty Acid | F11: 283 | G11: 96.729 | I11: T-20 | J11: 95.64 | L11: T-20 | M11: 35.427 | O11: T-20 | P11: =G11+J11+M11 -> 227.796 | Q11: =P11+'5 Feb''26'!Q11 -> 703.018
C12: Glycerine Water | F12: 231 | G12: 65.488 | I12: T-10 | J12: 66.141 | L12: T-10 | M12: 12.208 | O12: T-10 | P12: =G12+J12+M12 -> 143.837 | Q12: =P12+'5 Feb''26'!Q12 -> 514.353
A13: 102 | C13: Glycerine Water Feed | F13: 120 | G13: 39.052 | H13: 0 | I13: T-10 | J13: 40.882 | K13: 0 | L13: T-10 | M13: 43.194 | N13: 0 | O13: T-10 | P13: =G13+J13+M13 -> 123.128 | Q13: =P13+'5 Feb''26'!Q13 -> 352.8 | R13: =H13+K13+N13+'5 Feb''26'!R13 -> 55
C14: Treated Glycerine Water | F14: 120 | G14: 10.319 | I14: T-13 | J14: 26.216 | L14: T-13 | M14: 26.291 | O14: T-13 | P14: =G14+J14+M14 -> 62.826 | Q14: =P14+'5 Feb''26'!Q14 -> 206.023
A15: 103 | C15: Treated Gly Water Feed | F15: 120 | G15: 24.163 | H15: 0 | I15: T-13 | J15: 25.952 | K15: 0 | L15: T-13 | M15: 26.527 | N15: 0 | O15: T-13 | P15: =G15+J15+M15 -> 76.642 | Q15: =P15+'5 Feb''26'!Q15 -> 307.492 | R15: =H15+K15+N15+'5 Feb''26'!R15 -> 52.5
C16: Crude Glycerine | F16: 41 | G16: 9.53 | I16: T-14 | J16: 9.839 | L16: T-14 | M16: 9.525 | O16: T-14 | P16: =G16+J16+M16 -> 28.894 | Q16: =P16+'5 Feb''26'!Q16 -> 122.551
A17: 104 | C17: Crude Glycerine Feed | F17: 49 | G17: 8.307 | H17: 0 | I17: T-14 | J17: 7.943 | K17: 0 | L17: T-14 | M17: 9.661 | N17: 0 | O17: T-14 | P17: =G17+J17+M17 -> 25.911 | Q17: =P17+'5 Feb''26'!Q17 -> 89.105 | R17: =H17+K17+N17+'5 Feb''26'!R17 -> 76
C18: Refined Glycerine | F18: 40 | G18: 6.216 | I18: T-16 | J18: 8.245 | L18: T-16 | M18: 10.123 | O18: T-16 | P18: =G18+J18+M18 -> 24.584 | Q18: =P18+'5 Feb''26'!Q18 -> 77.373
C19: Glycerine Dist. II | F19: 2.21 | G19: 0.6 | I19: T-10 | J19: 0.25 | L19: T-10 | M19: 0.606 | O19: T-10 | P19: =G19+J19+M19 -> 1.456 | Q19: =P19+'5 Feb''26'!Q19 -> 5.309
C20: Pitch Glycerine | F20: 1.2 | G20: 0.25 | I20: Drum | J20: 0 | L20: Drum | M20: 0.5 | O20: Drum | P20: =G20+J20+M20 -> 0.75 | Q20: =P20+'5 Feb''26'!Q20 -> 2.125
A21: 105 | C21: Crude F.Acid / Feed I | F21: 300 | G21: 99.284 | H21: 0 | I21: T-20 | J21: 102.69 | K21: 0 | L21: T-20 | M21: 99.317 | N21: 0 | O21: T-20 | P21: =G21+J21+M21 -> 301.291 | Q21: =P21+'5 Feb''26'!Q21 -> 467.727 | R21: =H21+K21+N21+'5 Feb''26'!R21 -> 107.5
C22: Hydro F.Acid / Feed II | F22: 170 | G22: 0 | I22: - | J22: 0 | L22: - | M22: 0 | O22: - | P22: =G22+J22+M22 -> 0 | Q22: =P22+'5 Feb''26'!Q22 -> 0
C23: Light End | F23: 1.80 | G23: 0 | I23: - | J23: 0 | L23: - | M23: 0 | O23: - | P23: =G23+J23+M23 -> 0 | Q23: =P23+'5 Feb''26'!Q23 -> 0
C24: Top Fraction / C6-8 | F24: 1.56 | G24: 0.206 | I24: T-90 | J24: 0.216 | L24: T-90 | M24: 0.313 | O24: T-90 | P24: =G24+J24+M24 -> 0.735 | Q24: =P24+'5 Feb''26'!Q24 -> 1.034
C25: Side Fraction I / C8-10 | F25: 23.06 | G25: 7.113 | I25: F-07/06 | J25: 7.35 | L25: F-06/07 | M25: 6.861 | O25: F-07/06 | P25: =G25+J25+M25 -> 21.324 | Q25: =P25+'5 Feb''26'!Q25 -> 30.362
C26: Side Fr action II / C12-70 | F26: 188.33 | G26: 58 | I26: T-31 | J26: 59.84 | L26: T-31 | M26: 58.425 | O26: T-31 | P26: =G26+J26+M26 -> 176.265 | Q26: =P26+'5 Feb''26'!Q26 -> 246.26
C27: Side Fraction C16-95 | F27: 141.23 | G27: 0 | I27: - | J27: 0 | L27: - | M27: 0 | O27: - | P27: =G27+J27+M27 -> 0 | Q27: =P27+'5 Feb''26'!Q27 -> 0
C28: Distillate / C16-18 (PK) | F28: 75.55 | G28: 24.573 | I28: T-34 | J28: 25.596 | L28: T-34 | M28: 24.67 | O28: T-34 | P28: =G28+J28+M28 -> 74.839 | Q28: =P28+'5 Feb''26'!Q28 -> 106.079
C29: Distillate / C16-18 (PS) | F29: 146.71 | G29: 0 | I29: - | J29: 0 | L29: - | M29: 0 | O29: - | P29: =G29+J29+M29 -> 0 | Q29: =P29+'5 Feb''26'!Q29 -> 0
C30: Heavy End | F30: N/A | G30: 3.17 | I30: T-26 | J30: 3.456 | L30: T-26 | M30: 3.262 | O30: T-26 | P30: =G30+J30+M30 -> 9.888 | Q30: =P30+'5 Feb''26'!Q30 -> 12.797
C31: Fatty Acid Residue | F31: 9.7 | G31: 0.86 | I31: T-35 | J31: 0.805 | L31: T-35 | M31: 0.317 | O31: T-35 | P31: =G31+J31+M31 -> 1.982 | Q31: =P31+'5 Feb''26'!Q31 -> 2.792
A32: 107 | C32: C16-18 UH Feed | F32: 201 | G32: 0 | H32: 8 | I32: T- | J32: 0 | K32: 8 | L32: T- | M32: 0 | N32: 8 | O32: T- | P32: =G32+J32+M32 -> 0 | Q32: =P32+'5 Feb''26'!Q32 -> 0 | R32: =H32+K32+N32+'5 Feb''26'!R32 -> 144
C33: C16-18 Hydro Product | F33: 200 | G33: 0 | I33: T- | J33: 0 | L33: T- | M33: 0 | O33: T- | P33: =G33+J33+M33 -> 0 | Q33: =P33+'5 Feb''26'!Q33 -> 0

Sheet 7 Feb'26
A5: Operation Date | D5: 07 Feb' 2026
A7: I. Production
A8: Sect. | C8: Description | F8: Capacity | G8: Shift I | I8: Storage | J8: Shift II | L8: Storage | M8: Shift III | O8: Storage | P8: To Day | Q8: MTD | R8: D. Time
F9: MT/Day | G9: Product | H9: D.Time | I9: 122T... | J9: Product | K9: D.Time | L9: 122T... | M9: Product | N9: D.Time | O9: 122T... | R9: MTD
A10: 101 | C10: Feed ( CPKO / RBDPS ) | F10: 300 | G10: 85.329 | H10: 0 | I10: T-01 | J10: 100.529 | K10: 0 | L10: T-01 | M10: 101.199 | N10: 0 | O10: T-01 | P10: =G10+J10+M10 -> 287.057 | Q10: =P10+'6 Feb''26'!Q10 -> 1059.58 | R10: =H10+K10+N10+'6 Feb''26'!R10 -> 55.5
C11: Crude Fatty Acid | F11: 283 | G11: 80.433 | I11: T-20 | J11: 97.09 | L11: T-20 | M11: 97.049 | O11: T-20 | P11: =G11+J11+M11 -> 274.572 | Q11: =P11+'6 Feb''26'!Q11 -> 977.59
C12: Glycerine Water | F12: 231 | G12: 57.213 | I12: T-10 | J12: 65.712 | L12: T-10 | M12: 66.57 | O12: T-10 | P12: =G12+J12+M12 -> 189.495 | Q12: =P12+'6 Feb''26'!Q12 -> 703.848
A13: 102 | C13: Glycerine Water Feed | F13: 120 | G13: 42.585 | H13: 0 | I13: T-10 | J13: 43.039 | K13: 0 | L13: T-10 | M13: 44.146 | N13: 0 | O13: T-10 | P13: =G13+J13+M13 -> 129.77 | Q13: =P13+'6 Feb''26'!Q13 -> 482.57 | R13: =H13+K13+N13+'6 Feb''26'!R13 -> 55
C14: Treated Glycerine Water | F14: 120 | G14: 29.006 | I14: T-13 | J14: 23.87 | L14: T-13 | M14: 22.949 | O14: T-13 | P14: =G14+J14+M14 -> 75.825 | Q14: =P14+'6 Feb''26'!Q14 -> 281.848
A15: 103 | C15: Treated Gly Water Feed | F15: 120 | G15: 26.605 | H15: 0 | I15: T-13 | J15: 27.417 | K15: 0 | L15: T-13 | M15: 28.087 | N15: 0 | O15: T-13 | P15: =G15+J15+M15 -> 82.109 | Q15: =P15+'6 Feb''26'!Q15 -> 389.601 | R15: =H15+K15+N15+'6 Feb''26'!R15 -> 52.5
C16: Crude Glycerine | F16: 41 | G16: 9.433 | I16: T-14 | J16: 9.676 | L16: T-14 | M16: 9.854 | O16: T-14 | P16: =G16+J16+M16 -> 28.963 | Q16: =P16+'6 Feb''26'!Q16 -> 151.514
A17: 104 | C17: Crude Glycerine Feed | F17: 49 | G17: 10.585 | H17: 0 | I17: T-14 | J17: 11.171 | K17: 0 | L17: T-14 | M17: 10.77 | N17: 0 | O17: T-14 | P17: =G17+J17+M17 -> 32.526 | Q17: =P17+'6 Feb''26'!Q17 -> 121.631 | R17: =H17+K17+N17+'6 Feb''26'!R17 -> 76
C18: Refined Glycerine | F18: 40 | G18: 9.298 | I18: T-16 | J18: 10.271 | L18: T-16/23 | M18: 9.152 | O18: T-23 | P18: =G18+J18+M18 -> 28.721 | Q18: =P18+'6 Feb''26'!Q18 -> 106.094
C19: Glycerine Dist. II | F19: 2.21 | G19: 0.5 | I19: T-10 | J19: 0.594 | L19: T-10 | M19: 1.062 | O19: T-10 | P19: =G19+J19+M19 -> 2.156 | Q19: =P19+'6 Feb''26'!Q19 -> 7.465
C20: Pitch Glycerine | F20: 1.2 | G20: 0 | I20: Drum | J20: 0.5 | L20: Drum | M20: 0.375 | O20: Drum | P20: =G20+J20+M20 -> 0.875 | Q20: =P20+'6 Feb''26'!Q20 -> 3
A21: 105 | C21: Crude F.Acid / Feed I | F21: 300 | G21: 98.408 | H21: 0 | I21: T-20 | J21: 100.808 | K21: 0 | L21: T-20 | M21: 100.844 | N21: 0 | O21: T-20 | P21: =G21+J21+M21 -> 300.06 | Q21: =P21+'6 Feb''26'!Q21 -> 767.787 | R21: =H21+K21+N21+'6 Feb''26'!R21 -> 107.5
C22: Hydro F.Acid / Feed II | F22: 170 | G22: 0 | I22: - | J22: 0 | L22: - | M22: 0 | O22: - | P22: =G22+J22+M22 -> 0 | Q22: =P22+'6 Feb''26'!Q22 -> 0
C23: Light End | F23: 1.80 | G23: 0 | I23: - | J23: 0 | L23: - | M23: 0 | O23: - | P23: =G23+J23+M23 -> 0 | Q23: =P23+'6 Feb''26'!Q23 -> 0
C24: Top Fraction / C6-8 | F24: 1.56 | G24: 0.34 | I24: T-90 | J24: 0.347 | L24: T-90 | M24: 0.347 | O24: T-90 | P24: =G24+J24+M24 -> 1.034 | Q24: =P24+'6 Feb''26'!Q24 -> 2.068
C25: Side Fraction I / C8-10 | F25: 23.06 | G25: 6.818 | I25: F-06/07 | J25: 7.115 | L25: F-06/07 | M25: 6.962 | O25: F-07 | P25: =G25+J25+M25 -> 20.895 | Q25: =P25+'6 Feb''26'!Q25 -> 51.257
C26: Side Fr action II / C12-70 | F26: 188.33 | G26: 58.447 | I26: T-31 | J26: 59.271 | L26: T-31 | M26: 59.213 | O26: T-31 | P26: =G26+J26+M26 -> 176.931 | Q26: =P26+'6 Feb''26'!Q26 -> 423.191
C27: Side Fraction C16-98 | F27: 141.23 | G27: 0 | I27: - | J27: 0 | L27: - | M27: 0 | O27: - | P27: =G27+J27+M27 -> 0 | Q27: =P27+'6 Feb''26'!Q27 -> 0
C28: Distillate / C16-18 (PK) | F28: 75.55 | G28: 24.439 | I28: T-34 | J28: 25.843 | L28: T-34 | M28: 25.651 | O28: T-34 | P28: =G28+J28+M28 -> 75.933 | Q28: =P28+'6 Feb''26'!Q28 -> 182.012
C29: Distillate / C16-18 (PS) | F29: 146.71 | G29: 0 | I29: - | J29: 0 | L29: - | M29: 0 | O29: - | P29: =G29+J29+M29 -> 0 | Q29: =P29+'6 Feb''26'!Q29 -> 0
C30: Heavy End | F30: N/A | G30: 3.262 | I30: T-26 | J30: 3.038 | L30: T-26 | M30: 3.432 | O30: T-26 | P30: =G30+J30+M30 -> 9.732 | Q30: =P30+'6 Feb''26'!Q30 -> 22.529
C31: Fatty Acid Residue | F31: 9.7 | G31: 0.5 | I31: T-35 | J31: 0.611 | L31: T-35 | M31: 1.239 | O31: T-35 | P31: =G31+J31+M31 -> 2.35 | Q31: =P31+'6 Feb''26'!Q31 -> 5.142
A32: 107 | C32: C16-18 UH Feed | F32: 201 | G32: 0 | H32: 8 | I32: T- | J32: 0 | K32: 8 | L32: T- | M32: 0 | N32: 8 | O32: T- | P32: =G32+J32+M32 -> 0 | Q32: =P32+'6 Feb''26'!Q32 -> 0 | R32: =H32+K32+N32+'6 Feb''26'!R32 -> 168
C33: C16-18 Hydro Product | F33: 200 | G33: 0 | I33: T- | J33: 0 | L33: T- | M33: 0 | O33: T- | P33: =G33+J33+M33 -> 0 | Q33: =P33+'6 Feb''26'!Q33 -> 0

Sheet 8 Feb'26
A5: Operation Date | D5: 08 Feb' 2026
A7: I. Production
A8: Sect. | C8: Description | F8: Capacity | G8: Shift I | I8: Storage | J8: Shift II | L8: Storage | M8: Shift III | O8: Storage | P8: To Day | Q8: MTD | R8: D. Time
F9: MT/Day | G9: Product | H9: D.Time | I9: 122T... | J9: Product | K9: D.Time | L9: 122T... | M9: Product | N9: D.Time | O9: 122T... | R9: MTD
A10: 101 | C10: Feed ( CPKO / RBDPS ) | F10: 300 | G10: 99.324 | H10: 0 | I10: T-01 | J10: 101.266 | K10: 0 | L10: T-01 | M10: 101.768 | N10: 0 | O10: T-01 | P10: =G10+J10+M10 -> 302.358 | Q10: =P10+'7 Feb''26'!Q10 -> 1361.938 | R10: =H10+K10+N10+'7 Feb''26'!R10 -> 55.5
C11: Crude Fatty Acid | F11: 283 | G11: 95.694 | I11: T-20 | J11: 97.348 | L11: T-20 | M11: 98.432 | O11: T-20 | P11: =G11+J11+M11 -> 291.474 | Q11: =P11+'7 Feb''26'!Q11 -> 1269.064
C12: Glycerine Water | F12: 231 | G12: 64.979 | I12: T-10 | J12: 65.883 | L12: T-10 | M12: 65.952 | O12: T-10 | P12: =G12+J12+M12 -> 196.814 | Q12: =P12+'7 Feb''26'!Q12 -> 900.662
A13: 102 | C13: Glycerine Water Feed | F13: 120 | G13: 43.532 | H13: 0 | I13: T-10 | J13: 44.789 | K13: 0 | L13: T-10 | M13: 44.896 | N13: 0 | O13: T-10 | P13: =G13+J13+M13 -> 133.217 | Q13: =P13+'7 Feb''26'!Q13 -> 615.787 | R13: =H13+K13+N13+'7 Feb''26'!R13 -> 55
C14: Treated Glycerine Water | F14: 120 | G14: 24.072 | I14: T-13 | J14: 10.52 | L14: T-13 | M14: 32.798 | O14: T-13 | P14: =G14+J14+M14 -> 67.39 | Q14: =P14+'7 Feb''26'!Q14 -> 349.238
A15: 103 | C15: Treated Gly Water Feed | F15: 120 | G15: 29.377 | H15: 0 | I15: T-13 | J15: 30.746 | K15: 0 | L15: T-13 | M15: 32.839 | N15: 0 | O15: T-13 | P15: =G15+J15+M15 -> 92.962 | Q15: =P15+'7 Feb''26'!Q15 -> 482.563 | R15: =H15+K15+N15+'7 Feb''26'!R15 -> 52.5
C16: Crude Glycerine | F16: 41 | G16: 10.325 | I16: T-14 | J16: 10.52 | L16: T-14 | M16: 10.576 | O16: T-14 | P16: =G16+J16+M16 -> 31.421 | Q16: =P16+'7 Feb''26'!Q16 -> 182.935
A17: 104 | C17: Crude Glycerine Feed | F17: 49 | G17: 11.392 | H17: 0 | I17: T-14 | J17: 11.335 | K17: 0 | L17: T-14 | M17: 9.933 | N17: 0 | O17: T-14 | P17: =G17+J17+M17 -> 32.66 | Q17: =P17+'7 Feb''26'!Q17 -> 154.291 | R17: =H17+K17+N17+'7 Feb''26'!R17 -> 76
C18: Refined Glycerine | F18: 40 | G18: 10.232 | I18: T-23 | J18: 11.781 | L18: T-23 | M18: 9.64 | O18: T-23 | P18: =G18+J18+M18 -> 31.653 | Q18: =P18+'7 Feb''26'!Q18 -> 137.747
C19: Glycerine Dist. II | F19: 2.21 | G19: 0.6 | I19: T-10 | J19: 1.115 | L19: T-10 | M19: 0.866 | O19: T-10 | P19: =G19+J19+M19 -> 2.581 | Q19: =P19+'7 Feb''26'!Q19 -> 10.046
C20: Pitch Glycerine | F20: 1.2 | G20: 0.5 | I20: Drum | J20: 0 | L20: Drum | M20: 0.375 | O20: Drum | P20: =G20+J20+M20 -> 0.875 | Q20: =P20+'7 Feb''26'!Q20 -> 3.875
A21: 105 | C21: Crude F.Acid / Feed I | F21: 300 | G21: 99.349 | H21: 0 | I21: T-20 | J21: 101.213 | K21: 0 | L21: T-20 | M21: 101.694 | N21: 0 | O21: T-20 | P21: =G21+J21+M21 -> 302.256 | Q21: =P21+'7 Feb''26'!Q21 -> 1070.043 | R21: =H21+K21+N21+'7 Feb''26'!R21 -> 107.5
C22: Hydro F.Acid / Feed II | F22: 170 | G22: 0 | I22: - | J22: 0 | L22: - | M22: 0 | O22: - | P22: =G22+J22+M22 -> 0 | Q22: =P22+'7 Feb''26'!Q22 -> 0
C23: Light End | F23: 1.80 | G23: 0 | I23: - | J23: 0 | L23: - | M23: 0 | O23: - | P23: =G23+J23+M23 -> 0 | Q23: =P23+'7 Feb''26'!Q23 -> 0
C24: Top Fraction / C6-8 | F24: 1.56 | G24: 0.342 | I24: T-90 | J24: 0.348 | L24: T-90 | M24: 0.35 | O24: T-90 | P24: =G24+J24+M24 -> 1.04 | Q24: =P24+'7 Feb''26'!Q24 -> 3.108
C25: Side Fraction I / C8-10 | F25: 23.06 | G25: 6.914 | I25: F-07 | J25: 6.933 | L25: F-07 | M25: 6.873 | O25: F-07 | P25: =G25+J25+M25 -> 20.72 | Q25: =P25+'7 Feb''26'!Q25 -> 71.977
C26: Side Fr action II / C12-70 | F26: 188.33 | G26: 58.227 | I26: T-31 | J26: 59.189 | L26: T-31 | M26: 59.987 | O26: T-31 | P26: =G26+J26+M26 -> 177.403 | Q26: =P26+'7 Feb''26'!Q26 -> 600.594
C27: Side Fraction C16-98 | F27: 141.23 | G27: 0 | I27: - | J27: 0 | L27: - | M27: 0 | O27: - | P27: =G27+J27+M27 -> 0 | Q27: =P27+'7 Feb''26'!Q27 -> 0
C28: Distillate / C16-18 (PK) | F28: 75.55 | G28: 25.309 | I28: T-34 | J28: 26.07 | L28: T-34 | M28: 25.833 | O28: T-34 | P28: =G28+J28+M28 -> 77.212 | Q28: =P28+'7 Feb''26'!Q28 -> 259.224
C29: Distillate / C16-18 (PS) | F29: 146.71 | G29: 0 | I29: - | J29: 0 | L29: - | M29: 0 | O29: - | P29: =G29+J29+M29 -> 0 | Q29: =P29+'7 Feb''26'!Q29 -> 0
C30: Heavy End | F30: N/A | G30: 3.355 | I30: T-26 | J30: 3.303 | L30: T-26 | M30: 0 | O30: T-26 | P30: =G30+J30+M30 -> 6.658 | Q30: =P30+'7 Feb''26'!Q30 -> 29.187
C31: Fatty Acid Residue | F31: 9.7 | G31: 0.956 | I31: T-35 | J31: 0.897 | L31: T-35 | M31: 0.995 | O31: T-35 | P31: =G31+J31+M31 -> 2.848 | Q31: =P31+'7 Feb''26'!Q31 -> 7.99
A32: 107 | C32: C16-18 UH Feed | F32: 201 | G32: 0 | H32: 8 | I32: T- | J32: 0 | K32: 8 | L32: T- | M32: 0 | N32: 8 | O32: T- | P32: =G32+J32+M32 -> 0 | Q32: =P32+'7 Feb''26'!Q32 -> 0 | R32: =H32+K32+N32+'7 Feb''26'!R32 -> 192
C33: C16-18 Hydro Product | F33: 200 | G33: 0 | I33: T- | J33: 0 | L33: T- | M33: 0 | O33: T- | P33: =G33+J33+M33 -> 0 | Q33: =P33+'7 Feb''26'!Q33 -> 0

Sheet 9 Feb'26
A5: Operation Date | D5: 09 Feb' 2026
A7: I. Production
A8: Sect. | C8: Description | F8: Capacity | G8: Shift I | I8: Storage | J8: Shift II | L8: Storage | M8: Shift III | O8: Storage | P8: To Day | Q8: MTD | R8: D. Time
F9: MT/Day | G9: Product | H9: D.Time | I9: 122T... | J9: Product | K9: D.Time | L9: 122T... | M9: Product | N9: D.Time | O9: 122T... | R9: MTD
A10: 101 | C10: Feed ( CPKO / RBDPS ) | F10: 300 | G10: 95.437 | H10: 0 | I10: T-01 | J10: 90.945 | K10: 0 | L10: T-01 | M10: 78.352 | N10: 0 | O10: T-01 | P10: =G10+J10+M10 -> 264.734 | Q10: =P10+'8 Feb''26'!Q10 -> 1626.672 | R10: =H10+K10+N10+'8 Feb''26'!R10 -> 55.5
C11: Crude Fatty Acid | F11: 283 | G11: 91.362 | I11: T-20 | J11: 86.749 | L11: T-20 | M11: 75.541 | O11: T-20/25 | P11: =G11+J11+M11 -> 253.652 | Q11: =P11+'8 Feb''26'!Q11 -> 1522.716
C12: Glycerine Water | F12: 231 | G12: 62.285 | I12: T-10 | J12: 61.308 | L12: T-10 | M12: 53.197 | O12: T-10 | P12: =G12+J12+M12 -> 176.79 | Q12: =P12+'8 Feb''26'!Q12 -> 1077.452
A13: 102 | C13: Glycerine Water Feed | F13: 120 | G13: 42.084 | H13: 0 | I13: T-10 | J13: 45.871 | K13: 0 | L13: T-10 | M13: 43.014 | N13: 0 | O13: T-10 | P13: =G13+J13+M13 -> 130.969 | Q13: =P13+'8 Feb''26'!Q13 -> 746.756 | R13: =H13+K13+N13+'8 Feb''26'!R13 -> 55
C14: Treated Glycerine Water | F14: 120 | G14: 26.407 | I14: T-13 | J14: 24.536 | L14: T-13 | M14: 37.724 | O14: T-13 | P14: =G14+J14+M14 -> 88.667 | Q14: =P14+'8 Feb''26'!Q14 -> 437.905
A15: 103 | C15: Treated Gly Water Feed | F15: 120 | G15: 29.966 | H15: 0 | I15: T-13 | J15: 32.239 | K15: 0 | L15: T-13 | M15: 30.249 | N15: 0 | O15: T-13 | P15: =G15+J15+M15 -> 92.454 | Q15: =P15+'8 Feb''26'!Q15 -> 575.017 | R15: =H15+K15+N15+'8 Feb''26'!R15 -> 52.5
C16: Crude Glycerine | F16: 41 | G16: 9.92 | I16: T-14 | J16: 10.798 | L16: T-14 | M16: 10.127 | O16: T-14 | P16: =G16+J16+M16 -> 30.845 | Q16: =P16+'8 Feb''26'!Q16 -> 213.78
A17: 104 | C17: Crude Glycerine Feed | F17: 49 | G17: 10.686 | H17: 0 | I17: T-14 | J17: 11.629 | K17: 0 | L17: T-14 | M17: 12.093 | N17: 0 | O17: T-14 | P17: =G17+J17+M17 -> 34.408 | Q17: =P17+'8 Feb''26'!Q17 -> 188.699 | R17: =H17+K17+N17+'8 Feb''26'!R17 -> 76
C18: Refined Glycerine | F18: 40 | G18: 9.981 | I18: T-2316 | J18: 13.184 | L18: T-16 | M18: 11.127 | O18: T-16 | P18: =G18+J18+M18 -> 34.292 | Q18: =P18+'8 Feb''26'!Q18 -> 172.039
C19: Glycerine Dist. II | F19: 2.21 | G19: 0.65 | I19: T-10 | J19: 0.891 | L19: T-10 | M19: 0.799 | O19: T-10 | P19: =G19+J19+M19 -> 2.34 | Q19: =P19+'8 Feb''26'!Q19 -> 12.386
C20: Pitch Glycerine | F20: 1.2 | G20: 0.5 | I20: Drum | J20: 0.5 | L20: Drum | M20: 0 | O20: Drum | P20: =G20+J20+M20 -> 1 | Q20: =P20+'8 Feb''26'!Q20 -> 4.875
A21: 105 | C21: Crude F.Acid / Feed I | F21: 300 | G21: 95.54 | H21: 0 | I21: T-20 | J21: 0 | K21: 8 | L21: T-21 | M21: 27.585 | N21: 3.5 | O21: T-21 | P21: =G21+J21+M21 -> 123.125 | Q21: =P21+'8 Feb''26'!Q21 -> 1193.168 | R21: =H21+K21+N21+'8 Feb''26'!R21 -> 119
C22: Hydro F.Acid / Feed II | F22: 170 | G22: 0 | I22: - | J22: 0 | L22: - | M22: 0 | O22: - | P22: =G22+J22+M22 -> 0 | Q22: =P22+'8 Feb''26'!Q22 -> 0
C23: Light End | F23: 1.80 | G23: 0 | I23: - | J23: 0 | L23: - | M23: 0.65 | O23: - | P23: =G23+J23+M23 -> 0.65 | Q23: =P23+'8 Feb''26'!Q23 -> 0.65
C24: Top Fraction / C6-8 | F24: 1.56 | G24: 0.325 | I24: T-90 | J24: 0 | L24: T-21 | M24: 0.112 | O24: T-21/90 | P24: =G24+J24+M24 -> 0.437 | Q24: =P24+'8 Feb''26'!Q24 -> 3.545
C25: Side Fraction I / C8-10 | F25: 23.06 | G25: 6.491 | I25: F-07 | J25: 0 | L25: T-21 | M25: 5.494 | O25: T-21/F-06 | P25: =G25+J25+M25 -> 11.985 | Q25: =P25+'8 Feb''26'!Q25 -> 83.962
C26: Side Fr action II / C12-70 | F26: 188.33 | G26: 56.113 | I26: T-31 | J26: 0 | L26: T-21 | M26: 4.802 | O26: T-21/30 | P26: =G26+J26+M26 -> 60.915 | Q26: =P26+'8 Feb''26'!Q26 -> 661.509
C27: Side Fraction C16-98 | F27: 141.23 | G27: 0 | I27: - | J27: 0 | L27: - | M27: 0 | O27: - | P27: =G27+J27+M27 -> 0 | Q27: =P27+'8 Feb''26'!Q27 -> 0
C28: Distillate / C16-18 (PK) | F28: 75.55 | G28: 24.432 | I28: T-34 | J28: 0 | L28: T-21 | M28: 11.958 | O28: T-21/33 | P28: =G28+J28+M28 -> 36.39 | Q28: =P28+'8 Feb''26'!Q28 -> 295.614
C29: Distillate / C16-18 (PS) | F29: 146.71 | G29: 0 | I29: - | J29: 0 | L29: - | M29: 0 | O29: - | P29: =G29+J29+M29 -> 0 | Q29: =P29+'8 Feb''26'!Q29 -> 0
C30: Heavy End | F30: N/A | G30: 3.111 | I30: T-26 | J30: 0 | L30: T-21 | M30: 0 | O30: - | P30: =G30+J30+M30 -> 3.111 | Q30: =P30+'8 Feb''26'!Q30 -> 32.298
C31: Fatty Acid Residue | F31: 9.7 | G31: 0.971 | I31: T-35 | J31: 0 | L31: T-21 | M31: 1.202 | O31: T-21/35 | P31: =G31+J31+M31 -> 2.173 | Q31: =P31+'8 Feb''26'!Q31 -> 10.163
A32: 107 | C32: C16-18 UH Feed | F32: 201 | G32: 0 | H32: 8 | I32: T- | J32: 0 | K32: 8 | L32: T- | M32: 0 | N32: 8 | O32: T- | P32: =G32+J32+M32 -> 0 | Q32: =P32+'8 Feb''26'!Q32 -> 0 | R32: =H32+K32+N32+'8 Feb''26'!R32 -> 216
C33: C16-18 Hydro Product | F33: 200 | G33: 0 | I33: T- | J33: 0 | L33: T- | M33: 0 | O33: T- | P33: =G33+J33+M33 -> 0 | Q33: =P33+'8 Feb''26'!Q33 -> 0

Sheet 10 Feb'26
A5: Operation Date | D5: 10 Feb' 2026
A7: I. Production
A8: Sect. | C8: Description | F8: Capacity | G8: Shift I | I8: Storage | J8: Shift II | L8: Storage | M8: Shift III | O8: Storage | P8: To Day | Q8: MTD | R8: D. Time
F9: MT/Day | G9: Product | H9: D.Time | I9: 122T... | J9: Product | K9: D.Time | L9: 122T... | M9: Product | N9: D.Time | O9: 122T... | R9: MTD
A10: 101 | C10: Feed ( CPKO / RBDPS ) | F10: 300 | G10: 80.256 | H10: 0 | I10: T-01 | J10: 79.938 | K10: 0 | L10: T-01 | M10: 80.435 | N10: 0 | O10: T-01 | P10: =G10+J10+M10 -> 240.629 | Q10: =P10+'9 Feb''26'!Q10 -> 1867.301 | R10: =H10+K10+N10+'9 Feb''26'!R10 -> 55.5
C11: Crude Fatty Acid | F11: 283 | G11: 76.643 | I11: T-25 | J11: 77.014 | L11: T-25 | M11: 77.202 | O11: T-25 | P11: =G11+J11+M11 -> 230.859 | Q11: =P11+'9 Feb''26'!Q11 -> 1753.575
C12: Glycerine Water | F12: 231 | G12: 55.049 | I12: T-10 | J12: 54.018 | L12: T-10 | M12: 54.884 | O12: T-10 | P12: =G12+J12+M12 -> 163.951 | Q12: =P12+'9 Feb''26'!Q12 -> 1241.403
A13: 102 | C13: Glycerine Water Feed | F13: 120 | G13: 44.057 | H13: 0 | I13: T-10 | J13: 43.76 | K13: 0 | L13: T-10 | M13: 43.048 | N13: 0 | O13: T-10 | P13: =G13+J13+M13 -> 130.865 | Q13: =P13+'9 Feb''26'!Q13 -> 877.621 | R13: =H13+K13+N13+'9 Feb''26'!R13 -> 55
C14: Treated Glycerine Water | F14: 120 | G14: 19.633 | I14: T-13 | J14: 31.666 | L14: T-13 | M14: 37.244 | O14: T-13 | P14: =G14+J14+M14 -> 88.543 | Q14: =P14+'9 Feb''26'!Q14 -> 526.448
A15: 103 | C15: Treated Gly Water Feed | F15: 120 | G15: 31.563 | H15: 0 | I15: T-13 | J15: 31.445 | K15: 0 | L15: T-13 | M15: 31.824 | N15: 0 | O15: T-13 | P15: =G15+J15+M15 -> 94.832 | Q15: =P15+'9 Feb''26'!Q15 -> 669.849 | R15: =H15+K15+N15+'9 Feb''26'!R15 -> 52.5
C16: Crude Glycerine | F16: 41 | G16: 10.399 | I16: T-14 | J16: 10.362 | L16: T-14 | M16: 10.401 | O16: T-14 | P16: =G16+J16+M16 -> 31.162 | Q16: =P16+'9 Feb''26'!Q16 -> 244.942
A17: 104 | C17: Crude Glycerine Feed | F17: 49 | G17: 13.598 | H17: 0 | I17: T-14 | J17: 13.211 | K17: 0 | L17: T-14 | M17: 14.128 | N17: 0 | O17: T-14 | P17: =G17+J17+M17 -> 40.937 | Q17: =P17+'9 Feb''26'!Q17 -> 229.636 | R17: =H17+K17+N17+'9 Feb''26'!R17 -> 76
C18: Refined Glycerine | F18: 40 | G18: 15.29 | I18: T-16 | J18: 15.195 | L18: T-16/23 | M18: 14.647 | O18: T-23 | P18: =G18+J18+M18 -> 45.132 | Q18: =P18+'9 Feb''26'!Q18 -> 217.171
C19: Glycerine Dist. II | F19: 2.21 | G19: 1.104 | I19: T-10 | J19: 1.173 | L19: T-10 | M19: 0.303 | O19: T-10 | P19: =G19+J19+M19 -> 2.58 | Q19: =P19+'9 Feb''26'!Q19 -> 14.966
C20: Pitch Glycerine | F20: 1.2 | G20: 0.5 | I20: Drum | J20: 0 | L20: Drum | M20: 0 | O20: Drum | P20: =G20+J20+M20 -> 0.5 | Q20: =P20+'9 Feb''26'!Q20 -> 5.375
A21: 105 | C21: Crude F.Acid / Feed I | F21: 300 | G21: 48.099 | H21: 0 | I21: T-21 | J21: 53.769 | K21: 0 | L21: T-21 | M21: 36.89 | N21: 3 | O21: T-21 | P21: =G21+J21+M21 -> 138.758 | Q21: =P21+'9 Feb''26'!Q21 -> 1331.926 | R21: =H21+K21+N21+'9 Feb''26'!R21 -> 122
C22: Hydro F.Acid / Feed II | F22: 170 | G22: 0 | I22: - | J22: 0 | L22: - | M22: 0 | O22: - | P22: =G22+J22+M22 -> 0 | Q22: =P22+'9 Feb''26'!Q22 -> 0
C23: Light End | F23: 1.80 | G23: 0 | I23: - | J23: 0 | L23: - | M23: 0.306 | O23: - | P23: =G23+J23+M23 -> 0.306 | Q23: =P23+'9 Feb''26'!Q23 -> 0.956
C24: Top Fraction / C6-8 | F24: 1.56 | G24: 0.121 | I24: T-90/Drum | J24: 0.112 | L24: Drum | M24: 0.066 | O24: Drum | P24: =G24+J24+M24 -> 0.299 | Q24: =P24+'9 Feb''26'!Q24 -> 3.844
C25: Side Fraction I / C8-10 | F25: 23.06 | G25: 8.832 | I25: F-07 | J25: 9.849 | L25: F-07 | M25: 6.298 | O25: F-07 | P25: =G25+J25+M25 -> 24.979 | Q25: =P25+'9 Feb''26'!Q25 -> 108.941
C26: Side Fr action II / C12-70 | F26: 188.33 | G26: 8.036 | I26: T-30 | J26: 7.62 | L26: T-30 | M26: 5.343 | O26: T-30 | P26: =G26+J26+M26 -> 20.999 | Q26: =P26+'9 Feb''26'!Q26 -> 682.508
C27: Side Fraction C16-98 | F27: 141.23 | G27: 0 | I27: - | J27: 0 | L27: - | M27: 0 | O27: - | P27: =G27+J27+M27 -> 0 | Q27: =P27+'9 Feb''26'!Q27 -> 0
C28: Distillate / C16-18 (PK) | F28: 75.55 | G28: 23.44 | I28: T-33 | J28: 25.615 | L28: T-33 | M28: 18.073 | O28: T-33 | P28: =G28+J28+M28 -> 67.128 | Q28: =P28+'9 Feb''26'!Q28 -> 362.742
C29: Distillate / C16-18 (PS) | F29: 146.71 | G29: 0 | I29: - | J29: 0 | L29: - | M29: 0 | O29: - | P29: =G29+J29+M29 -> 0 | Q29: =P29+'9 Feb''26'!Q29 -> 0
C30: Heavy End | F30: N/A | G30: 0 | I30: - | J30: 0 | L30: - | M30: 0 | O30: - | P30: =G30+J30+M30 -> 0 | Q30: =P30+'9 Feb''26'!Q30 -> 32.298
C31: Fatty Acid Residue | F31: 9.7 | G31: 0.597 | I31: T-35 | J31: 1.192 | L31: T-35 | M31: 1.325 | O31: T-35 | P31: =G31+J31+M31 -> 3.114 | Q31: =P31+'9 Feb''26'!Q31 -> 13.277
A32: 107 | C32: C16-18 UH Feed | F32: 201 | G32: 0 | H32: 8 | I32: T- | J32: 0 | K32: 8 | L32: T- | M32: 0 | N32: 8 | O32: T- | P32: =G32+J32+M32 -> 0 | Q32: =P32+'9 Feb''26'!Q32 -> 0 | R32: =H32+K32+N32+'9 Feb''26'!R32 -> 240
C33: C16-18 Hydro Product | F33: 200 | G33: 0 | I33: T- | J33: 0 | L33: T- | M33: 0 | O33: T- | P33: =G33+J33+M33 -> 0 | Q33: =P33+'9 Feb''26'!Q33 -> 0
D84: Shift 1 Spv | G84: Shift 2 Spv | J84: Shift 3 Spv | P84: Fatty Acid Spt

Sheet 11 Feb'26 
A5: Operation Date | D5: 11 Feb' 2026
A7: I. Production
A8: Sect. | C8: Description | F8: Capacity | G8: Shift I | I8: Storage | J8: Shift II | L8: Storage | M8: Shift III | O8: Storage | P8: To Day | Q8: MTD | R8: D. Time
F9: MT/Day | G9: Product | H9: D.Time | I9: 122T... | J9: Product | K9: D.Time | L9: 122T... | M9: Product | N9: D.Time | O9: 122T... | R9: MTD
A10: 101 | C10: Feed ( CPKO / RBDPS ) | F10: 300 | G10: 81.686 | H10: 0 | I10: T-01 | J10: 78.968 | K10: 0 | L10: T-01 | M10: 79.863 | N10: 0 | O10: T-01 | P10: =G10+J10+M10 -> 240.517 | Q10: =P10+'10 Feb''26'!Q10 -> 2107.818 | R10: =H10+K10+N10+'10 Feb''26'!R10 -> 55.5
C11: Crude Fatty Acid | F11: 283 | G11: 78.306 | I11: T-25 | J11: 75.835 | L11: T-25/20 | M11: 75.955 | O11: T-20 | P11: =G11+J11+M11 -> 230.096 | Q11: =P11+'10 Feb''26'!Q11 -> 1983.671
C12: Glycerine Water | F12: 231 | G12: 55.674 | I12: T-10 | J12: 53.906 | L12: T-10 | M12: 54.727 | O12: T-10 | P12: =G12+J12+M12 -> 164.307 | Q12: =P12+'10 Feb''26'!Q12 -> 1405.71
A13: 102 | C13: Glycerine Water Feed | F13: 120 | G13: 43.739 | H13: 0 | I13: T-10 | J13: 43.087 | K13: 0 | L13: T-10 | M13: 42.165 | N13: 0 | O13: T-10 | P13: =G13+J13+M13 -> 128.991 | Q13: =P13+'10 Feb''26'!Q13 -> 1006.612 | R13: =H13+K13+N13+'10 Feb''26'!R13 -> 55
C14: Treated Glycerine Water | F14: 120 | G14: 32.919 | I14: T-13 | J14: 31.239 | L14: T-13 | M14: 24.791 | O14: T-13 | P14: =G14+J14+M14 -> 88.949 | Q14: =P14+'10 Feb''26'!Q14 -> 615.397
A15: 103 | C15: Treated Gly Water Feed | F15: 120 | G15: 31.477 | H15: 0 | I15: T-13 | J15: 31.151 | K15: 0 | L15: T-13 | M15: 31.013 | N15: 0 | O15: T-13 | P15: =G15+J15+M15 -> 93.641 | Q15: =P15+'10 Feb''26'!Q15 -> 763.49 | R15: =H15+K15+N15+'10 Feb''26'!R15 -> 52.5
C16: Crude Glycerine | F16: 41 | G16: 11.667 | I16: T-14 | J16: 13.857 | L16: T-14 | M16: 13.848 | O16: T-14 | P16: =G16+J16+M16 -> 39.372 | Q16: =P16+'10 Feb''26'!Q16 -> 284.314
A17: 104 | C17: Crude Glycerine Feed | F17: 49 | G17: 14.638 | H17: 0 | I17: T-14 | J17: 13.087 | K17: 0 | L17: T-14 | M17: 14.269 | N17: 0 | O17: T-14 | P17: =G17+J17+M17 -> 41.994 | Q17: =P17+'10 Feb''26'!Q17 -> 271.63 | R17: =H17+K17+N17+'10 Feb''26'!R17 -> 76
C18: Refined Glycerine | F18: 40 | G18: 14.696 | I18: T-23 | J18: 13.141 | L18: T-23 | M18: 15.195 | O18: T-23/16 | P18: =G18+J18+M18 -> 43.032 | Q18: =P18+'10 Feb''26'!Q18 -> 260.203
C19: Glycerine Dist. II | F19: 2.21 | G19: 0.691 | I19: T-10 | J19: 0.657 | L19: T-10 | M19: 0 | O19: T-10 | P19: =G19+J19+M19 -> 1.348 | Q19: =P19+'10 Feb''26'!Q19 -> 16.314
C20: Pitch Glycerine | F20: 1.2 | G20: 0.5 | I20: Drum | J20: 0.5 | L20: Drum | M20: 0 | O20: Drum | P20: =G20+J20+M20 -> 1 | Q20: =P20+'10 Feb''26'!Q20 -> 6.375
A21: 105 | C21: Crude F.Acid / Feed I | F21: 300 | G21: 0 | H21: 8 | I21: T-20 | J21: 47.347 | K21: 3 | L21: T-20 | M21: 99.604 | N21: 0 | O21: T-20 | P21: =G21+J21+M21 -> 146.951 | Q21: =P21+'10 Feb''26'!Q21 -> 1478.877 | R21: =H21+K21+N21+'10 Feb''26'!R21 -> 133
C22: Hydro F.Acid / Feed II | F22: 170 | G22: 0 | I22: - | J22: 0 | L22: - | M22: 0 | O22: - | P22: =G22+J22+M22 -> 0 | Q22: =P22+'10 Feb''26'!Q22 -> 0
C23: Light End | F23: 1.80 | G23: 0 | I23: - | J23: 0 | L23: - | M23: 0 | O23: - | P23: =G23+J23+M23 -> 0 | Q23: =P23+'10 Feb''26'!Q23 -> 0.956
C24: Top Fraction / C6-8 | F24: 1.56 | G24: 0 | I24: T-20 | J24: 0.073 | L24: T-20/Drum | M24: 0.119 | O24: Drum | P24: =G24+J24+M24 -> 0.192 | Q24: =P24+'10 Feb''26'!Q24 -> 4.036
C25: Side Fraction I / C8-10 | F25: 23.06 | G25: 0 | I25: F- | J25: 3.145 | L25: T-20/F-07 | M25: 7.249 | O25: F-07 | P25: =G25+J25+M25 -> 10.394 | Q25: =P25+'10 Feb''26'!Q25 -> 119.335
C26: Side Fr action II / C12-70 | F26: 188.33 | G26: 0 | I26: T-20 | J26: 27.022 | L26: T-20/31 | M26: 57.583 | O26: T-31 | P26: =G26+J26+M26 -> 84.605 | Q26: =P26+'10 Feb''26'!Q26 -> 767.113
C27: Side Fraction C16-98 | F27: 141.23 | G27: 0 | I27: - | J27: 0 | L27: - | M27: 0 | O27: - | P27: =G27+J27+M27 -> 0 | Q27: =P27+'10 Feb''26'!Q27 -> 0
C28: Distillate / C16-18 (PK) | F28: 75.55 | G28: 0 | I28: T-20 | J28: 11.98 | L28: T-20/34 | M28: 24.384 | O28: T-34 | P28: =G28+J28+M28 -> 36.364 | Q28: =P28+'10 Feb''26'!Q28 -> 399.106
C29: Distillate / C16-18 (PS) | F29: 146.71 | G29: 0 | I29: - | J29: 0 | L29: - | M29: 0 | O29: - | P29: =G29+J29+M29 -> 0 | Q29: =P29+'10 Feb''26'!Q29 -> 0
C30: Heavy End | F30: N/A | G30: 0 | I30: - | J30: 1.851 | L30: - | M30: 5.26 | O30: - | P30: =G30+J30+M30 -> 7.111 | Q30: =P30+'10 Feb''26'!Q30 -> 39.409
C31: Fatty Acid Residue | F31: 9.7 | G31: 0 | I31: T- | J31: 0.564 | L31: T--20/35 | M31: 0.654 | O31: T-35 | P31: =G31+J31+M31 -> 1.218 | Q31: =P31+'10 Feb''26'!Q31 -> 14.495
A32: 107 | C32: C16-18 UH Feed | F32: 201 | G32: 0 | H32: 8 | I32: T- | J32: 0 | K32: 8 | L32: T- | M32: 0 | N32: 8 | O32: T- | P32: =G32+J32+M32 -> 0 | Q32: =P32+'10 Feb''26'!Q32 -> 0 | R32: =H32+K32+N32+'10 Feb''26'!R32 -> 264
C33: C16-18 Hydro Product | F33: 200 | G33: 0 | I33: T- | J33: 0 | L33: T- | M33: 0 | O33: T- | P33: =G33+J33+M33 -> 0 | Q33: =P33+'10 Feb''26'!Q33 -> 0

Sheet 12 Feb'26
A5: Operation Date | D5: 12 Feb' 2026
A7: I. Production
A8: Sect. | C8: Description | F8: Capacity | G8: Shift I | I8: Storage | J8: Shift II | L8: Storage | M8: Shift III | O8: Storage | P8: To Day | Q8: MTD | R8: D. Time
F9: MT/Day | G9: Product | H9: D.Time | I9: 122T... | J9: Product | K9: D.Time | L9: 122T... | M9: Product | N9: D.Time | O9: 122T... | R9: MTD
A10: 101 | C10: Feed ( CPKO / RBDPS ) | F10: 300 | G10: 79.252 | H10: 0 | I10: T-01 | J10: 81.605 | K10: 0 | L10: T-01 | M10: 77.561 | N10: 0 | O10: T-01 | P10: =G10+J10+M10 -> 238.418 | Q10: =P10+'11 Feb''26 '!Q10 -> 2346.236 | R10: =H10+K10+N10+'11 Feb''26 '!R10 -> 55.5
C11: Crude Fatty Acid | F11: 283 | G11: 75.989 | I11: T-20 | J11: 78.483 | L11: T-20 | M11: 74.459 | O11: T-20 | P11: =G11+J11+M11 -> 228.931 | Q11: =P11+'11 Feb''26 '!Q11 -> 2212.602
C12: Glycerine Water | F12: 231 | G12: 54.403 | I12: T-10 | J12: 56.309 | L12: T-10 | M12: 53.979 | O12: T-10 | P12: =G12+J12+M12 -> 164.691 | Q12: =P12+'11 Feb''26 '!Q12 -> 1570.401
A13: 102 | C13: Glycerine Water Feed | F13: 120 | G13: 41.995 | H13: 0 | I13: T-10 | J13: 43.286 | K13: 0 | L13: T-10 | M13: 40.974 | N13: 0 | O13: T-10 | P13: =G13+J13+M13 -> 126.255 | Q13: =P13+'11 Feb''26 '!Q13 -> 1132.867 | R13: =H13+K13+N13+'11 Feb''26 '!R13 -> 55
C14: Treated Glycerine Water | F14: 120 | G14: 29.15 | I14: T-13 | J14: 21.034 | L14: T-13 | M14: 36.016 | O14: T-13 | P14: =G14+J14+M14 -> 86.2 | Q14: =P14+'11 Feb''26 '!Q14 -> 701.597
A15: 103 | C15: Treated Gly Water Feed | F15: 120 | G15: 31.081 | H15: 0 | I15: T-13 | J15: 32.354 | K15: 0 | L15: T-13 | M15: 30.563 | N15: 0 | O15: T-13 | P15: =G15+J15+M15 -> 93.998 | Q15: =P15+'11 Feb''26 '!Q15 -> 857.488 | R15: =H15+K15+N15+'11 Feb''26 '!R15 -> 52.5
C16: Crude Glycerine | F16: 41 | G16: 13.984 | I16: T-14 | J16: 14.855 | L16: T-14 | M16: 14.038 | O16: T-14 | P16: =G16+J16+M16 -> 42.877 | Q16: =P16+'11 Feb''26 '!Q16 -> 327.191
A17: 104 | C17: Crude Glycerine Feed | F17: 49 | G17: 14.237 | H17: 0 | I17: T-14 | J17: 14.542 | K17: 0 | L17: T-14 | M17: 13.906 | N17: 0 | O17: T-14 | P17: =G17+J17+M17 -> 42.685 | Q17: =P17+'11 Feb''26 '!Q17 -> 314.315 | R17: =H17+K17+N17+'11 Feb''26 '!R17 -> 76
C18: Refined Glycerine | F18: 40 | G18: 14.777 | I18: T-16 | J18: 15.67 | L18: T-16 | M18: 14.833 | O18: T-16 | P18: =G18+J18+M18 -> 45.28 | Q18: =P18+'11 Feb''26 '!Q18 -> 305.483
C19: Glycerine Dist. II | F19: 2.21 | G19: 0.6 | I19: T-10 | J19: 0.712 | L19: T-10 | M19: 0.587 | O19: T-10 | P19: =G19+J19+M19 -> 1.899 | Q19: =P19+'11 Feb''26 '!Q19 -> 18.213
C20: Pitch Glycerine | F20: 1.2 | G20: 0.5 | I20: Drum | J20: 0.5 | L20: Drum | M20: 0 | O20: Drum | P20: =G20+J20+M20 -> 1 | Q20: =P20+'11 Feb''26 '!Q20 -> 7.375
A21: 105 | C21: Crude F.Acid / Feed I | F21: 300 | G21: 102.957 | H21: 0 | I21: T-20 | J21: 51.409 | K21: 4.25 | L21: T-20 | M21: 95.225 | N21: 0 | O21: T-20 | P21: =G21+J21+M21 -> 249.591 | Q21: =P21+'11 Feb''26 '!Q21 -> 1728.468 | R21: =H21+K21+N21+'11 Feb''26 '!R21 -> 137.25
C22: Hydro F.Acid / Feed II | F22: 170 | G22: 0 | I22: - | J22: 0 | L22: - | M22: 0 | O22: - | P22: =G22+J22+M22 -> 0 | Q22: =P22+'11 Feb''26 '!Q22 -> 0
C23: Light End | F23: 1.80 | G23: 0 | I23: - | J23: 0 | L23: - | M23: 0 | O23: - | P23: =G23+J23+M23 -> 0 | Q23: =P23+'11 Feb''26 '!Q23 -> 0.956
C24: Top Fraction / C6-8 | F24: 1.56 | G24: 0.119 | I24: Drum | J24: 0.118 | L24: Drum/T-90 | M24: 0.283 | O24: T-90 | P24: =G24+J24+M24 -> 0.52 | Q24: =P24+'11 Feb''26 '!Q24 -> 4.556
C25: Side Fraction I / C8-10 | F25: 23.06 | G25: 7.531 | I25: F-06 | J25: 3.497 | L25: F-06/07 | M25: 6.381 | O25: F-07 | P25: =G25+J25+M25 -> 17.409 | Q25: =P25+'11 Feb''26 '!Q25 -> 136.744
C26: Side Fr action II / C12-70 | F26: 188.33 | G26: 60.498 | I26: T-31 | J26: 30.084 | L26: T-31 | M26: 55.931 | O26: T-31 | P26: =G26+J26+M26 -> 146.513 | Q26: =P26+'11 Feb''26 '!Q26 -> 913.626
C27: Side Fraction C16-98 | F27: 141.23 | G27: 0 | I27: - | J27: 0 | L27: - | M27: 0 | O27: - | P27: =G27+J27+M27 -> 0 | Q27: =P27+'11 Feb''26 '!Q27 -> 0
C28: Distillate / C16-18 (PK) | F28: 75.55 | G28: 26.025 | I28: T-34 | J28: 12.87 | L28: T-34 | M28: 25.16 | O28: T-34 | P28: =G28+J28+M28 -> 64.055 | Q28: =P28+'11 Feb''26 '!Q28 -> 463.161
C29: Distillate / C16-18 (PS) | F29: 146.71 | G29: 0 | I29: - | J29: 0 | L29: - | M29: 0 | O29: - | P29: =G29+J29+M29 -> 0 | Q29: =P29+'11 Feb''26 '!Q29 -> 0
C30: Heavy End | F30: N/A | G30: 3.7 | I30: - | J30: 1.708 | L30: - | M30: 2.131 | O30: - | P30: =G30+J30+M30 -> 7.539 | Q30: =P30+'11 Feb''26 '!Q30 -> 46.948
C31: Fatty Acid Residue | F31: 9.7 | G31: 0.912 | I31: T-35 | J31: 0.406 | L31: T-35 | M31: 0.512 | O31: T-35 | P31: =G31+J31+M31 -> 1.83 | Q31: =P31+'11 Feb''26 '!Q31 -> 16.325
A32: 107 | C32: C16-18 UH Feed | F32: 201 | G32: 0 | H32: 8 | I32: T- | J32: 0 | K32: 8 | L32: T- | M32: 0 | N32: 8 | O32: T- | P32: =G32+J32+M32 -> 0 | Q32: =P32+'11 Feb''26 '!Q32 -> 0 | R32: =H32+K32+N32+'11 Feb''26 '!R32 -> 288
C33: C16-18 Hydro Product | F33: 200 | G33: 0 | I33: T- | J33: 0 | L33: T- | M33: 0 | O33: T- | P33: =G33+J33+M33 -> 0 | Q33: =P33+'11 Feb''26 '!Q33 -> 0

Sheet 13 Feb'26
A5: Operation Date | D5: 13 Feb' 2026
A7: I. Production
A8: Sect. | C8: Description | F8: Capacity | G8: Shift I | I8: Storage | J8: Shift II | L8: Storage | M8: Shift III | O8: Storage | P8: To Day | Q8: MTD | R8: D. Time
F9: MT/Day | G9: Product | H9: D.Time | I9: 122T... | J9: Product | K9: D.Time | L9: 122T... | M9: Product | N9: D.Time | O9: 122T... | R9: MTD
A10: 101 | C10: Feed ( CPKO / RBDPS ) | F10: 300 | G10: 81.04 | H10: 0 | I10: T-01 | J10: 81.19 | K10: 0 | L10: T-01 | M10: 78.505 | N10: 0 | O10: T-01 | P10: =G10+J10+M10 -> 240.735 | Q10: =P10+'12 Feb''26'!Q10 -> 2586.971 | R10: =H10+K10+N10+'12 Feb''26'!R10 -> 55.5
C11: Crude Fatty Acid | F11: 283 | G11: 77.821 | I11: T-20 | J11: 78.119 | L11: T-20 | M11: 75.449 | O11: T-20 | P11: =G11+J11+M11 -> 231.389 | Q11: =P11+'12 Feb''26'!Q11 -> 2443.991
C12: Glycerine Water | F12: 231 | G12: 56.332 | I12: T-10 | J12: 55.871 | L12: T-10 | M12: 53.91 | O12: T-10 | P12: =G12+J12+M12 -> 166.113 | Q12: =P12+'12 Feb''26'!Q12 -> 1736.514
